Workbook

Sheet Lisez-moi
A1: COMPAS — RÉFÉRENTIEL DE SAISIE
A2: Rôle | B2: Ce classeur est l'interface de saisie des données structurées du site. Il est importé par le script d'import (spec docs/specs/05-import-excel.md), qui génère les fichiers JSON de data/ et met à jour l'en-tête des fiches Markdown. Ne modifie plus les JSON à la main : c'est ce classeur qui fait foi.
A3: Ce qui ne va PAS ici | B3: Le texte rédigé des fiches (définition, principes fondamentaux, mises en œuvre historiques) s'écrit directement dans src/content/courants/<id>.md. Modèle : ecosocialisme.md.
A4: Emplacement du fichier | B4: data/source/compas-referentiel.xlsx dans le dépôt.
A6: LÉGENDE
A7: Cellule jaune | B7: À remplir par toi.
A8: Cellule grise | B8: Calculée par formule : ne pas modifier.
A9: Cellule blanche | B9: Pré-remplie (catalogue, relations, thématiques) : à corriger si besoin.
A10: Listes déroulantes | B10: Familles, modules, verdicts, types de relation, couches, statuts : les valeurs autorisées sont dans l'onglet Listes.
A12: CONVENTIONS
A13: Identifiants | B13: kebab-case, sans accents ni espaces : marxisme-leninisme, etat-pouvoir. Un identifiant ne change plus une fois publié.
A14: Valeurs multiples | B14: Séparées par « ; » : marxismes ; liberalismes
A15: Textes de référence | B15: Titre (Auteurs, année) ; Titre 2 (Auteur, année)
A16: Sources | B16: Référence complète ou URL, séparées par « ; ». Un score sans source est affiché comme provisoire.
A17: Notes | B17: De 0 à 10, décimales autorisées (6,5). Orientation fixée par le critère (Économie : 10 = pôle marchand).
A18: Fourchette | B18: min et max optionnels, quand le courant est ambigu sur le critère. Sinon, laisser vide.
A19: Couche | B19: doctrine = le courant tel qu'il se pense ; historique = ce qu'en ont fait les régimes qui s'en réclament (optionnel).
A20: Dates | B20: Repères de maquette à vérifier : passe a_verifier à « non » une fois la date sourcée.
A22: ORDRE DE SAISIE CONSEILLÉ
A23: 1. Critères | B23: Reporter les 7 critères économiques de ton Excel d'origine (libellés, pôles, ancres), puis ceux d'État et pouvoir.
A24: 2. Scores | B24: Onglet Scores : les lignes des 16 courants du MVP × 7 critères économiques sont prêtes. La colonne contrôle signale les oublis.
A25: 3. Courants | B25: Compléter l'identité des courants du MVP (colonne mvp = oui), puis les autres.
A26: 4. Tribunal et relations | B26: Ajouter les idées reçues et vérifier les filiations.
A28: EXEMPLE DE LIGNE (onglet Scores) | B28: courant : social-democratie · critere : eco-1 · couche : doctrine · valeur : 6 · min : 5 · max : 7 · conteste : non · justification : « Économie mixte, propriété privée dominante et secteur public stratégique » · sources : référence de l'ouvrage ou du texte programmatique
A30: Matrice_Economie | B30: Vue de contrôle en lecture seule : les notes doctrine de l'onglet Scores croisées courants × critères, avec une échelle de couleur.

Sheet Courants
A1: id | B1: nom | C1: famille | D1: lignees | E1: modules | F1: alias | G1: emergence_annee | H1: emergence_libelle | I1: a_verifier | J1: textes_reference | K1: figures | L1: en_dialogue_avec | M1: statut | N1: mvp | O1: sources
A2: liberalisme-classique | B2: Libéralisme classique | C2: liberalismes | G2: 1776 | I2: oui | M2: a_rediger | N2: oui
A3: minarchisme | B3: Minarchisme | C3: liberalismes | F3: État minimal | M3: a_rediger | N3: oui
A4: georgisme | B4: Géorgisme | C4: liberalismes | G4: 1879 | I4: oui | M4: a_rediger | N4: non
A5: social-liberalisme | B5: Social-libéralisme | C5: liberalismes | G5: 1911 | I5: oui | M5: a_rediger | N5: non
A6: ordoliberalisme | B6: Ordolibéralisme | C6: liberalismes | G6: 1937 | I6: oui | M6: a_rediger | N6: non
A7: neoliberalisme | B7: Néolibéralisme | C7: liberalismes | G7: 1947 | I7: oui | M7: a_rediger | N7: non
A8: libertarianisme | B8: Libertarianisme | C8: liberalismes | G8: 1974 | I8: oui | M8: a_rediger | N8: non
A9: jacobinisme | B9: Jacobinisme | C9: republicanismes | G9: 1793 | I9: oui | M9: a_rediger | N9: oui
A10: radicalisme | B10: Radicalisme | C10: republicanismes | G10: 1901 | I10: oui | M10: a_rediger | N10: non
A11: laicisme | B11: Laïcisme | C11: republicanismes | G11: 1905 | I11: oui | M11: a_rediger | N11: non
A12: neo-republicanisme | B12: Néo-républicanisme | C12: republicanismes | G12: 1997 | I12: oui | M12: a_rediger | N12: non
A13: socialisme-utopique | B13: Socialisme utopique | C13: socialismes | G13: 1820 | I13: oui | M13: a_rediger | N13: non
A14: cooperatisme | B14: Coopératisme | C14: socialismes | G14: 1844 | I14: oui | M14: a_rediger | N14: non
A15: social-democratie | B15: Social-démocratie | C15: socialismes | D15: marxismes | G15: 1875 | I15: oui | M15: a_rediger | N15: oui
A16: distributisme | B16: Distributisme | C16: socialismes | D16: conservatismes | G16: 1912 | I16: oui | M16: a_rediger | N16: non
A17: socialisme-democratique | B17: Socialisme démocratique | C17: socialismes | G17: 1951 | I17: oui | M17: a_rediger | N17: non
A18: marxisme | B18: Marxisme | C18: marxismes | F18: Communisme (théorie) | G18: 1848 | I18: oui | M18: a_rediger | N18: oui
A19: leninisme | B19: Léninisme | C19: marxismes | G19: 1902 | I19: oui | M19: a_rediger | N19: non
A20: marxisme-leninisme | B20: Marxisme-léninisme | C20: marxismes | M20: a_rediger | N20: non
A21: conseillisme | B21: Conseillisme | C21: marxismes | G21: 1920 | I21: oui | M21: a_rediger | N21: non
A22: trotskysme | B22: Trotskysme | C22: marxismes | G22: 1928 | I22: oui | M22: a_rediger | N22: non
A23: maoisme | B23: Maoïsme | C23: marxismes | G23: 1949 | I23: oui | M23: a_rediger | N23: non
A24: posadisme | B24: Posadisme | C24: marxismes | G24: 1962 | I24: oui | M24: a_rediger | N24: non
A25: eurocommunisme | B25: Eurocommunisme | C25: marxismes | G25: 1975 | I25: oui | M25: a_rediger | N25: non
A26: mutuellisme | B26: Mutuellisme | C26: anarchismes | G26: 1840 | I26: oui | M26: a_rediger | N26: non
A27: anarcho-communisme | B27: Anarcho-communisme | C27: anarchismes | G27: 1876 | I27: oui | M27: a_rediger | N27: oui
A28: anarcho-syndicalisme | B28: Anarcho-syndicalisme | C28: anarchismes | G28: 1906 | I28: oui | M28: a_rediger | N28: non
A29: anarcho-capitalisme | B29: Anarcho-capitalisme | C29: anarchismes | D29: liberalismes | G29: 1973 | I29: oui | M29: a_rediger | N29: oui
A30: communalisme | B30: Communalisme | C30: anarchismes | D30: ecologismes | F30: Écologie sociale | G30: 1982 | I30: oui | M30: a_rediger | N30: non
A31: conservatisme-burkeen | B31: Conservatisme burkéen | C31: conservatismes | G31: 1790 | I31: oui | M31: a_rediger | N31: non
A32: democratie-chretienne | B32: Démocratie chrétienne | C32: conservatismes | D32: religieux | G32: 1891 | I32: oui | M32: a_rediger | N32: non
A33: corporatisme | B33: Corporatisme | C33: conservatismes | D33: fascismes | M33: a_rediger | N33: non
A34: gaullisme | B34: Gaullisme | C34: conservatismes | D34: autoritarismes | G34: 1947 | I34: oui | M34: a_rediger | N34: non
A35: neoconservatisme | B35: Néoconservatisme | C35: conservatismes | D35: marxismes | G35: 1972 | I35: oui | M35: a_rediger | N35: non
A36: paleoconservatisme | B36: Paléoconservatisme | C36: conservatismes | M36: a_rediger | N36: non
A37: conservatisme-liberal | B37: Conservatisme libéral | C37: conservatismes | D37: liberalismes | F37: Libéral-conservatisme | M37: a_rediger | N37: oui
A38: contre-revolution | B38: Contre-révolution | C38: traditionalismes | G38: 1796 | I38: oui | M38: a_rediger | N38: non
A39: maurrassisme | B39: Maurrassisme | C39: traditionalismes | G39: 1899 | I39: oui | M39: a_rediger | N39: non
A40: traditionalisme-integral | B40: Traditionalisme intégral | C40: traditionalismes | D40: religieux | G40: 1934 | I40: oui | M40: a_rediger | N40: non
...

Sheet Tribunal
A1: courant | B1: idee | C1: verdict | D1: explication | E1: sources
A2: ecosocialisme | B2: C’est du communisme repeint en vert. | C2: nuance | D2: La filiation marxiste est revendiquée. Mais le courant se construit aussi contre le productivisme des régimes soviétiques, dont il souligne le bilan écologique.
A3: ecosocialisme | B3: Il veut supprimer toute croissance. | C3: nuance | D3: Plusieurs auteurs défendent une décroissance sélective : réduire certains secteurs et en développer d’autres. La décroissance générale est la thèse d’un courant voisin, pas une position commune.

Sheet Relations
A1: source | B1: cible | C1: type | D1: date | E1: note | F1: sources | G1: a_verifier
A2: liberalisme-classique | B2: social-liberalisme | C2: derive | G2: oui
A3: liberalisme-classique | B3: ordoliberalisme | C3: derive | G3: oui
A4: liberalisme-classique | B4: neoliberalisme | C4: derive | G4: oui
A5: liberalisme-classique | B5: libertarianisme | C5: derive | G5: oui
A6: liberalisme-classique | B6: minarchisme | C6: derive | G6: oui
A7: minarchisme | B7: anarcho-capitalisme | C7: derive | G7: oui
A8: libertarianisme | B8: anarcho-capitalisme | C8: derive | G8: oui
A9: libertarianisme | B9: neocameralisme | C9: derive | G9: oui
A10: neocameralisme | B10: neoreaction | C10: derive | G10: oui
A11: socialisme-utopique | B11: marxisme | C11: derive | G11: oui
A12: marxisme | B12: leninisme | C12: derive | G12: oui
A13: leninisme | B13: trotskysme | C13: derive | G13: oui
... A40: mutuellisme | B40: anarcho-capitalisme | C40: synthese | G40: oui

Sheet Thematiques
A1: id | B1: nom | C1: ordre | D1: pole0 | E1: pole10 | F1: poles_valides | G1: orientation | H1: statut
A2: economie | B2: Économie | C2: 1 | D2: Planifié | E2: Marchand | F2: non | G2: 10 = pôle marchand sur chaque critère | H2: barème partiel : orientation fixée (10 = pôle marchand), 7 critères à reprendre de l'Excel
A3: etat-pouvoir | B3: État et pouvoir | C3: 2 | D3: Sans État | E3: État total | F3: non | H3: grille construite, barème à établir
A4: individu-societe | B4: Individu et société | C4: 3 | D4: Primauté du collectif | E4: Primauté de l'individu | F4: non | H4: grille construite, barème à établir
A5: temps-changement | B5: Temps et changement | C5: 4 | D5: Restauration | E5: Rupture | F5: non | H5: grille construite, barème à établir
A6: nation-identite | B6: Nation et identité | C6: 5 | D6: Universalisme | E6: Primauté nationale | F6: non | H6: grille construite, barème à établir
A7: epistemologie | B7: Épistémologie | C7: 6 | D7: Tradition, révélation | E7: Raison critique | F7: non | H7: grille construite, barème à établir
A8: ecologie | B8: Écologie | C8: 7 | D8: Productivisme | E8: Primauté du vivant | F8: non | H8: grille construite, barème à établir
A9: violence | B9: Violence | C9: 8 | D9: Non-violence | E9: Violence légitimée | F9: non | H9: grille construite, barème à établir
A10: religion-morale | B10: Religion et morale | C10: 9 | D10: Sécularisme | E10: Norme religieuse | F10: non | H10: grille construite, barème à établir
A11: genre-famille-moeurs | B11: Genre, famille, mœurs | C11: 10 | D11: Ordre traditionnel | E11: Égalité, libre choix | F11: non | H11: grille construite, barème à établir

Sheet Criteres
A1: theme | B1: id | C1: libelle | D1: pole0 | E1: pole10 | F1: ancre_0 | G1: ancre_2_5 | H1: ancre_5 | I1: ancre_7_5 | J1: ancre_10
A2: economie | B2: eco-1
A3: economie | B3: eco-2
A4: economie | B4: eco-3
A5: economie | B5: eco-4
A6: economie | B6: eco-5
A7: economie | B7: eco-6
A8: economie | B8: eco-7

Sheet Scores
A1: courant | B1: critere | C1: theme | D1: couche | E1: valeur | F1: min | G1: max | H1: conteste | I1: justification | J1: sources | K1: controle
A2: anarcho-capitalisme | B2: eco-1 | C2: =IFERROR(INDEX(Criteres!$A$2:$A$1000,MATCH(B2,Criteres!$B$2:$B$1000,0)),"") -> economie | D2: doctrine | K2: =IF(A2="","",IF(E2="","à noter",IF(OR(E2<0,E2>10),"hors échelle",IF(AND(F2<>"",F2>E2),"min > valeur",IF(AND(G2<>"",G2<E2),"max < valeur",IF(J2="","sans source","ok")))))) -> à noter
A3: anarcho-capitalisme | B3: eco-2 | C3: =IFERROR(INDEX(Criteres!$A$2:$A$1000,MATCH(B3,Criteres!$B$2:$B$1000,0)),"") -> economie | D3: doctrine | K3: =IF(A3="","",IF(E3="","à noter",IF(OR(E3<0,E3>10),"hors échelle",IF(AND(F3<>"",F3>E3),"min > valeur",IF(AND(G3<>"",G3<E3),"max < valeur",IF(J3="","sans source","ok")))))) -> à noter
A4: anarcho-capitalisme | B4: eco-3 | C4: =IFERROR(INDEX(Criteres!$A$2:$A$1000,MATCH(B4,Criteres!$B$2:$B$1000,0)),"") -> economie | D4: doctrine | K4: =IF(A4="","",IF(E4="","à noter",IF(OR(E4<0,E4>10),"hors échelle",IF(AND(F4<>"",F4>E4),"min > valeur",IF(AND(G4<>"",G4<E4),"max < valeur",IF(J4="","sans source","ok")))))) -> à noter
A5: anarcho-capitalisme | B5: eco-4 | C5: =IFERROR(INDEX(Criteres!$A$2:$A$1000,MATCH(B5,Criteres!$B$2:$B$1000,0)),"") -> economie | D5: doctrine | K5: =IF(A5="","",IF(E5="","à noter",IF(OR(E5<0,E5>10),"hors échelle",IF(AND(F5<>"",F5>E5),"min > valeur",IF(AND(G5<>"",G5<E5),"max < valeur",IF(J5="","sans source","ok")))))) -> à noter
A6: anarcho-capitalisme | B6: eco-5 | C6: =IFERROR(INDEX(Criteres!$A$2:$A$1000,MATCH(B6,Criteres!$B$2:$B$1000,0)),"") -> economie | D6: doctrine | K6: =IF(A6="","",IF(E6="","à noter",IF(OR(E6<0,E6>10),"hors échelle",IF(AND(F6<>"",F6>E6),"min > valeur",IF(AND(G6<>"",G6<E6),"max < valeur",IF(J6="","sans source","ok")))))) -> à noter
A7: anarcho-capitalisme | B7: eco-6 | C7: =IFERROR(INDEX(Criteres!$A$2:$A$1000,MATCH(B7,Criteres!$B$2:$B$1000,0)),"") -> economie | D7: doctrine | K7: =IF(A7="","",IF(E7="","à noter",IF(OR(E7<0,E7>10),"hors échelle",IF(AND(F7<>"",F7>E7),"min > valeur",IF(AND(G7<>"",G7<E7),"max < valeur",IF(J7="","sans source","ok")))))) -> à noter
A8: anarcho-capitalisme | B8: eco-7 | C8: =IFERROR(INDEX(Criteres!$A$2:$A$1000,MATCH(B8,Criteres!$B$2:$B$1000,0)),"") -> economie | D8: doctrine | K8: =IF(A8="","",IF(E8="","à noter",IF(OR(E8<0,E8>10),"hors échelle",IF(AND(F8<>"",F8>E8),"min > valeur",IF(AND(G8<>"",G8<E8),"max < valeur",IF(J8="","sans source","ok")))))) -> à noter
A9: marxisme | B9: eco-1 | C9: =IFERROR(INDEX(Criteres!$A$2:$A$1000,MATCH(B9,Criteres!$B$2:$B$1000,0)),"") -> economie | D9: doctrine | K9: =IF(A9="","",IF(E9="","à noter",IF(OR(E9<0,E9>10),"hors échelle",IF(AND(F9<>"",F9>E9),"min > valeur",IF(AND(G9<>"",G9<E9),"max < valeur",IF(J9="","sans source","ok")))))) -> à noter
A10: marxisme | B10: eco-2 | C10: =IFERROR(INDEX(Criteres!$A$2:$A$1000,MATCH(B10,Criteres!$B$2:$B$1000,0)),"") -> economie | D10: doctrine | K10: =IF(A10="","",IF(E10="","à noter",IF(OR(E10<0,E10>10),"hors échelle",IF(AND(F10<>"",F10>E10),"min > valeur",IF(AND(G10<>"",G10<E10),"max < valeur",IF(J10="","sans source","ok")))))) -> à noter
A11: marxisme | B11: eco-3 | C11: =IFERROR(INDEX(Criteres!$A$2:$A$1000,MATCH(B11,Criteres!$B$2:$B$1000,0)),"") -> economie | D11: doctrine | K11: =IF(A11="","",IF(E11="","à noter",IF(OR(E11<0,E11>10),"hors échelle",IF(AND(F11<>"",F11>E11),"min > valeur",IF(AND(G11<>"",G11<E11),"max < valeur",IF(J11="","sans source","ok")))))) -> à noter
A12: marxisme | B12: eco-4 | C12: =IFERROR(INDEX(Criteres!$A$2:$A$1000,MATCH(B12,Criteres!$B$2:$B$1000,0)),"") -> economie | D12: doctrine | K12: =IF(A12="","",IF(E12="","à noter",IF(OR(E12<0,E12>10),"hors échelle",IF(AND(F12<>"",F12>E12),"min > valeur",IF(AND(G12<>"",G12<E12),"max < valeur",IF(J12="","sans source","ok")))))) -> à noter
A13: marxisme | B13: eco-5 | C13: =IFERROR(INDEX(Criteres!$A$2:$A$1000,MATCH(B13,Criteres!$B$2:$B$1000,0)),"") -> economie | D13: doctrine | K13: =IF(A13="","",IF(E13="","à noter",IF(OR(E13<0,E13>10),"hors échelle",IF(AND(F13<>"",F13>E13),"min > valeur",IF(AND(G13<>"",G13<E13),"max < valeur",IF(J13="","sans source","ok")))))) -> à noter
... A113: neocameralisme | B113: eco-7 | C113: =IFERROR(INDEX(Criteres!$A$2:$A$1000,MATCH(B113,Criteres!$B$2:$B$1000,0)),"") -> economie | D113: doctrine | K113: =IF(A113="","",IF(E113="","à noter",IF(OR(E113<0,E113>10),"hors échelle",IF(AND(F113<>"",F113>E113),"min > valeur",IF(AND(G113<>"",G113<E113),"max < valeur",IF(J113="","sans source","ok")))))) -> à noter
C114: =IFERROR(INDEX(Criteres!$A$2:$A$1000,MATCH(B114,Criteres!$B$2:$B$1000,0)),"") | K114: =IF(A114="","",IF(E114="","à noter",IF(OR(E114<0,E114>10),"hors échelle",IF(AND(F114<>"",F114>E114),"min > valeur",IF(AND(G114<>"",G114<E114),"max < valeur",IF(J114="","sans source","ok"))))))
C115: =IFERROR(INDEX(Criteres!$A$2:$A$1000,MATCH(B115,Criteres!$B$2:$B$1000,0)),"") | K115: =IF(A115="","",IF(E115="","à noter",IF(OR(E115<0,E115>10),"hors échelle",IF(AND(F115<>"",F115>E115),"min > valeur",IF(AND(G115<>"",G115<E115),"max < valeur",IF(J115="","sans source","ok"))))))
C116: =IFERROR(INDEX(Criteres!$A$2:$A$1000,MATCH(B116,Criteres!$B$2:$B$1000,0)),"") | K116: =IF(A116="","",IF(E116="","à noter",IF(OR(E116<0,E116>10),"hors échelle",IF(AND(F116<>"",F116>E116),"min > valeur",IF(AND(G116<>"",G116<E116),"max < valeur",IF(J116="","sans source","ok"))))))
C117: =IFERROR(INDEX(Criteres!$A$2:$A$1000,MATCH(B117,Criteres!$B$2:$B$1000,0)),"") | K117: =IF(A117="","",IF(E117="","à noter",IF(OR(E117<0,E117>10),"hors échelle",IF(AND(F117<>"",F117>E117),"min > valeur",IF(AND(G117<>"",G117<E117),"max < valeur",IF(J117="","sans source","ok"))))))
C118: =IFERROR(INDEX(Criteres!$A$2:$A$1000,MATCH(B118,Criteres!$B$2:$B$1000,0)),"") | K118: =IF(A118="","",IF(E118="","à noter",IF(OR(E118<0,E118>10),"hors échelle",IF(AND(F118<>"",F118>E118),"min > valeur",IF(AND(G118<>"",G118<E118),"max < valeur",IF(J118="","sans source","ok"))))))
C119: =IFERROR(INDEX(Criteres!$A$2:$A$1000,MATCH(B119,Criteres!$B$2:$B$1000,0)),"") | K119: =IF(A119="","",IF(E119="","à noter",IF(OR(E119<0,E119>10),"hors échelle",IF(AND(F119<>"",F119>E119),"min > valeur",IF(AND(G119<>"",G119<E119),"max < valeur",IF(J119="","sans source","ok"))))))
C120: =IFERROR(INDEX(Criteres!$A$2:$A$1000,MATCH(B120,Criteres!$B$2:$B$1000,0)),"") | K120: =IF(A120="","",IF(E120="","à noter",IF(OR(E120<0,E120>10),"hors échelle",IF(AND(F120<>"",F120>E120),"min > valeur",IF(AND(G120<>"",G120<E120),"max < valeur",IF(J120="","sans source","ok"))))))
C121: =IFERROR(INDEX(Criteres!$A$2:$A$1000,MATCH(B121,Criteres!$B$2:$B$1000,0)),"") | K121: =IF(A121="","",IF(E121="","à noter",IF(OR(E121<0,E121>10),"hors échelle",IF(AND(F121<>"",F121>E121),"min > valeur",IF(AND(G121<>"",G121<E121),"max < valeur",IF(J121="","sans source","ok"))))))
C122: =IFERROR(INDEX(Criteres!$A$2:$A$1000,MATCH(B122,Criteres!$B$2:$B$1000,0)),"") | K122: =IF(A122="","",IF(E122="","à noter",IF(OR(E122<0,E122>10),"hors échelle",IF(AND(F122<>"",F122>E122),"min > valeur",IF(AND(G122<>"",G122<E122),"max < valeur",IF(J122="","sans source","ok"))))))
C123: =IFERROR(INDEX(Criteres!$A$2:$A$1000,MATCH(B123,Criteres!$B$2:$B$1000,0)),"") | K123: =IF(A123="","",IF(E123="","à noter",IF(OR(E123<0,E123>10),"hors échelle",IF(AND(F123<>"",F123>E123),"min > valeur",IF(AND(G123<>"",G123<E123),"max < valeur",IF(J123="","sans source","ok"))))))
C124: =IFERROR(INDEX(Criteres!$A$2:$A$1000,MATCH(B124,Criteres!$B$2:$B$1000,0)),"") | K124: =IF(A124="","",IF(E124="","à noter",IF(OR(E124<0,E124>10),"hors échelle",IF(AND(F124<>"",F124>E124),"min > valeur",IF(AND(G124<>"",G124<E124),"max < valeur",IF(J124="","sans source","ok"))))))
C125: =IFERROR(INDEX(Criteres!$A$2:$A$1000,MATCH(B125,Criteres!$B$2:$B$1000,0)),"") | K125: =IF(A125="","",IF(E125="","à noter",IF(OR(E125<0,E125>10),"hors échelle",IF(AND(F125<>"",F125>E125),"min > valeur",IF(AND(G125<>"",G125<E125),"max < valeur",IF(J125="","sans source","ok"))))))
... C263: =IFERROR(INDEX(Criteres!$A$2:$A$1000,MATCH(B263,Criteres!$B$2:$B$1000,0)),"") | K263: =IF(A263="","",IF(E263="","à noter",IF(OR(E263<0,E263>10),"hors échelle",IF(AND(F263<>"",F263>E263),"min > valeur",IF(AND(G263<>"",G263<E263),"max < valeur",IF(J263="","sans source","ok"))))))

Sheet Matrice_Economie
A1: courant | B1: eco-1 | C1: eco-2 | D1: eco-3 | E1: eco-4 | F1: eco-5 | G1: eco-6 | H1: eco-7 | I1: nb notes
A2: anarcho-capitalisme | B2: =IFERROR(AVERAGEIFS(Scores!$E$2:$E$263,Scores!$A$2:$A$263,$A2,Scores!$B$2:$B$263,B$1,Scores!$D$2:$D$263,"doctrine"),"") | C2: =IFERROR(AVERAGEIFS(Scores!$E$2:$E$263,Scores!$A$2:$A$263,$A2,Scores!$B$2:$B$263,C$1,Scores!$D$2:$D$263,"doctrine"),"") | D2: =IFERROR(AVERAGEIFS(Scores!$E$2:$E$263,Scores!$A$2:$A$263,$A2,Scores!$B$2:$B$263,D$1,Scores!$D$2:$D$263,"doctrine"),"") | E2: =IFERROR(AVERAGEIFS(Scores!$E$2:$E$263,Scores!$A$2:$A$263,$A2,Scores!$B$2:$B$263,E$1,Scores!$D$2:$D$263,"doctrine"),"") | F2: =IFERROR(AVERAGEIFS(Scores!$E$2:$E$263,Scores!$A$2:$A$263,$A2,Scores!$B$2:$B$263,F$1,Scores!$D$2:$D$263,"doctrine"),"") | G2: =IFERROR(AVERAGEIFS(Scores!$E$2:$E$263,Scores!$A$2:$A$263,$A2,Scores!$B$2:$B$263,G$1,Scores!$D$2:$D$263,"doctrine"),"") | H2: =IFERROR(AVERAGEIFS(Scores!$E$2:$E$263,Scores!$A$2:$A$263,$A2,Scores!$B$2:$B$263,H$1,Scores!$D$2:$D$263,"doctrine"),"") | I2: =COUNT(B2:H2) -> 0
A3: marxisme | B3: =IFERROR(AVERAGEIFS(Scores!$E$2:$E$263,Scores!$A$2:$A$263,$A3,Scores!$B$2:$B$263,B$1,Scores!$D$2:$D$263,"doctrine"),"") | C3: =IFERROR(AVERAGEIFS(Scores!$E$2:$E$263,Scores!$A$2:$A$263,$A3,Scores!$B$2:$B$263,C$1,Scores!$D$2:$D$263,"doctrine"),"") | D3: =IFERROR(AVERAGEIFS(Scores!$E$2:$E$263,Scores!$A$2:$A$263,$A3,Scores!$B$2:$B$263,D$1,Scores!$D$2:$D$263,"doctrine"),"") | E3: =IFERROR(AVERAGEIFS(Scores!$E$2:$E$263,Scores!$A$2:$A$263,$A3,Scores!$B$2:$B$263,E$1,Scores!$D$2:$D$263,"doctrine"),"") | F3: =IFERROR(AVERAGEIFS(Scores!$E$2:$E$263,Scores!$A$2:$A$263,$A3,Scores!$B$2:$B$263,F$1,Scores!$D$2:$D$263,"doctrine"),"") | G3: =IFERROR(AVERAGEIFS(Scores!$E$2:$E$263,Scores!$A$2:$A$263,$A3,Scores!$B$2:$B$263,G$1,Scores!$D$2:$D$263,"doctrine"),"") | H3: =IFERROR(AVERAGEIFS(Scores!$E$2:$E$263,Scores!$A$2:$A$263,$A3,Scores!$B$2:$B$263,H$1,Scores!$D$2:$D$263,"doctrine"),"") | I3: =COUNT(B3:H3) -> 0
A4: fascisme-italien | B4: =IFERROR(AVERAGEIFS(Scores!$E$2:$E$263,Scores!$A$2:$A$263,$A4,Scores!$B$2:$B$263,B$1,Scores!$D$2:$D$263,"doctrine"),"") | C4: =IFERROR(AVERAGEIFS(Scores!$E$2:$E$263,Scores!$A$2:$A$263,$A4,Scores!$B$2:$B$263,C$1,Scores!$D$2:$D$263,"doctrine"),"") | D4: =IFERROR(AVERAGEIFS(Scores!$E$2:$E$263,Scores!$A$2:$A$263,$A4,Scores!$B$2:$B$263,D$1,Scores!$D$2:$D$263,"doctrine"),"") | E4: =IFERROR(AVERAGEIFS(Scores!$E$2:$E$263,Scores!$A$2:$A$263,$A4,Scores!$B$2:$B$263,E$1,Scores!$D$2:$D$263,"doctrine"),"") | F4: =IFERROR(AVERAGEIFS(Scores!$E$2:$E$263,Scores!$A$2:$A$263,$A4,Scores!$B$2:$B$263,F$1,Scores!$D$2:$D$263,"doctrine"),"") | G4: =IFERROR(AVERAGEIFS(Scores!$E$2:$E$263,Scores!$A$2:$A$263,$A4,Scores!$B$2:$B$263,G$1,Scores!$D$2:$D$263,"doctrine"),"") | H4: =IFERROR(AVERAGEIFS(Scores!$E$2:$E$263,Scores!$A$2:$A$263,$A4,Scores!$B$2:$B$263,H$1,Scores!$D$2:$D$263,"doctrine"),"") | I4: =COUNT(B4:H4) -> 0
A5: social-democratie | B5: =IFERROR(AVERAGEIFS(Scores!$E$2:$E$263,Scores!$A$2:$A$263,$A5,Scores!$B$2:$B$263,B$1,Scores!$D$2:$D$263,"doctrine"),"") | C5: =IFERROR(AVERAGEIFS(Scores!$E$2:$E$263,Scores!$A$2:$A$263,$A5,Scores!$B$2:$B$263,C$1,Scores!$D$2:$D$263,"doctrine"),"") | D5: =IFERROR(AVERAGEIFS(Scores!$E$2:$E$263,Scores!$A$2:$A$263,$A5,Scores!$B$2:$B$263,D$1,Scores!$D$2:$D$263,"doctrine"),"") | E5: =IFERROR(AVERAGEIFS(Scores!$E$2:$E$263,Scores!$A$2:$A$263,$A5,Scores!$B$2:$B$263,E$1,Scores!$D$2:$D$263,"doctrine"),"") | F5: =IFERROR(AVERAGEIFS(Scores!$E$2:$E$263,Scores!$A$2:$A$263,$A5,Scores!$B$2:$B$263,F$1,Scores!$D$2:$D$263,"doctrine"),"") | G5: =IFERROR(AVERAGEIFS(Scores!$E$2:$E$263,Scores!$A$2:$A$263,$A5,Scores!$B$2:$B$263,G$1,Scores!$D$2:$D$263,"doctrine"),"") | H5: =IFERROR(AVERAGEIFS(Scores!$E$2:$E$263,Scores!$A$2:$A$263,$A5,Scores!$B$2:$B$263,H$1,Scores!$D$2:$D$263,"doctrine"),"") | I5: =COUNT(B5:H5) -> 0
A6: liberalisme-classique | B6: =IFERROR(AVERAGEIFS(Scores!$E$2:$E$263,Scores!$A$2:$A$263,$A6,Scores!$B$2:$B$263,B$1,Scores!$D$2:$D$263,"doctrine"),"") | C6: =IFERROR(AVERAGEIFS(Scores!$E$2:$E$263,Scores!$A$2:$A$263,$A6,Scores!$B$2:$B$263,C$1,Scores!$D$2:$D$263,"doctrine"),"") | D6: =IFERROR(AVERAGEIFS(Scores!$E$2:$E$263,Scores!$A$2:$A$263,$A6,Scores!$B$2:$B$263,D$1,Scores!$D$2:$D$263,"doctrine"),"") | E6: =IFERROR(AVERAGEIFS(Scores!$E$2:$E$263,Scores!$A$2:$A$263,$A6,Scores!$B$2:$B$263,E$1,Scores!$D$2:$D$263,"doctrine"),"") | F6: =IFERROR(AVERAGEIFS(Scores!$E$2:$E$263,Scores!$A$2:$A$263,$A6,Scores!$B$2:$B$263,F$1,Scores!$D$2:$D$263,"doctrine"),"") | G6: =IFERROR(AVERAGEIFS(Scores!$E$2:$E$263,Scores!$A$2:$A$263,$A6,Scores!$B$2:$B$263,G$1,Scores!$D$2:$D$263,"doctrine"),"") | H6: =IFERROR(AVERAGEIFS(Scores!$E$2:$E$263,Scores!$A$2:$A$263,$A6,Scores!$B$2:$B$263,H$1,Scores!$D$2:$D$263,"doctrine"),"") | I6: =COUNT(B6:H6) -> 0
A7: minarchisme | B7: =IFERROR(AVERAGEIFS(Scores!$E$2:$E$263,Scores!$A$2:$A$263,$A7,Scores!$B$2:$B$263,B$1,Scores!$D$2:$D$263,"doctrine"),"") | C7: =IFERROR(AVERAGEIFS(Scores!$E$2:$E$263,Scores!$A$2:$A$263,$A7,Scores!$B$2:$B$263,C$1,Scores!$D$2:$D$263,"doctrine"),"") | D7: =IFERROR(AVERAGEIFS(Scores!$E$2:$E$263,Scores!$A$2:$A$263,$A7,Scores!$B$2:$B$263,D$1,Scores!$D$2:$D$263,"doctrine"),"") | E7: =IFERROR(AVERAGEIFS(Scores!$E$2:$E$263,Scores!$A$2:$A$263,$A7,Scores!$B$2:$B$263,E$1,Scores!$D$2:$D$263,"doctrine"),"") | F7: =IFERROR(AVERAGEIFS(Scores!$E$2:$E$263,Scores!$A$2:$A$263,$A7,Scores!$B$2:$B$263,F$1,Scores!$D$2:$D$263,"doctrine"),"") | G7: =IFERROR(AVERAGEIFS(Scores!$E$2:$E$263,Scores!$A$2:$A$263,$A7,Scores!$B$2:$B$263,G$1,Scores!$D$2:$D$263,"doctrine"),"") | H7: =IFERROR(AVERAGEIFS(Scores!$E$2:$E$263,Scores!$A$2:$A$263,$A7,Scores!$B$2:$B$263,H$1,Scores!$D$2:$D$263,"doctrine"),"") | I7: =COUNT(B7:H7) -> 0
A8: jacobinisme | B8: =IFERROR(AVERAGEIFS(Scores!$E$2:$E$263,Scores!$A$2:$A$263,$A8,Scores!$B$2:$B$263,B$1,Scores!$D$2:$D$263,"doctrine"),"") | C8: =IFERROR(AVERAGEIFS(Scores!$E$2:$E$263,Scores!$A$2:$A$263,$A8,Scores!$B$2:$B$263,C$1,Scores!$D$2:$D$263,"doctrine"),"") | D8: =IFERROR(AVERAGEIFS(Scores!$E$2:$E$263,Scores!$A$2:$A$263,$A8,Scores!$B$2:$B$263,D$1,Scores!$D$2:$D$263,"doctrine"),"") | E8: =IFERROR(AVERAGEIFS(Scores!$E$2:$E$263,Scores!$A$2:$A$263,$A8,Scores!$B$2:$B$263,E$1,Scores!$D$2:$D$263,"doctrine"),"") | F8: =IFERROR(AVERAGEIFS(Scores!$E$2:$E$263,Scores!$A$2:$A$263,$A8,Scores!$B$2:$B$263,F$1,Scores!$D$2:$D$263,"doctrine"),"") | G8: =IFERROR(AVERAGEIFS(Scores!$E$2:$E$263,Scores!$A$2:$A$263,$A8,Scores!$B$2:$B$263,G$1,Scores!$D$2:$D$263,"doctrine"),"") | H8: =IFERROR(AVERAGEIFS(Scores!$E$2:$E$263,Scores!$A$2:$A$263,$A8,Scores!$B$2:$B$263,H$1,Scores!$D$2:$D$263,"doctrine"),"") | I8: =COUNT(B8:H8) -> 0
A9: anarcho-communisme | B9: =IFERROR(AVERAGEIFS(Scores!$E$2:$E$263,Scores!$A$2:$A$263,$A9,Scores!$B$2:$B$263,B$1,Scores!$D$2:$D$263,"doctrine"),"") | C9: =IFERROR(AVERAGEIFS(Scores!$E$2:$E$263,Scores!$A$2:$A$263,$A9,Scores!$B$2:$B$263,C$1,Scores!$D$2:$D$263,"doctrine"),"") | D9: =IFERROR(AVERAGEIFS(Scores!$E$2:$E$263,Scores!$A$2:$A$263,$A9,Scores!$B$2:$B$263,D$1,Scores!$D$2:$D$263,"doctrine"),"") | E9: =IFERROR(AVERAGEIFS(Scores!$E$2:$E$263,Scores!$A$2:$A$263,$A9,Scores!$B$2:$B$263,E$1,Scores!$D$2:$D$263,"doctrine"),"") | F9: =IFERROR(AVERAGEIFS(Scores!$E$2:$E$263,Scores!$A$2:$A$263,$A9,Scores!$B$2:$B$263,F$1,Scores!$D$2:$D$263,"doctrine"),"") | G9: =IFERROR(AVERAGEIFS(Scores!$E$2:$E$263,Scores!$A$2:$A$263,$A9,Scores!$B$2:$B$263,G$1,Scores!$D$2:$D$263,"doctrine"),"") | H9: =IFERROR(AVERAGEIFS(Scores!$E$2:$E$263,Scores!$A$2:$A$263,$A9,Scores!$B$2:$B$263,H$1,Scores!$D$2:$D$263,"doctrine"),"") | I9: =COUNT(B9:H9) -> 0
A10: conservatisme-liberal | B10: =IFERROR(AVERAGEIFS(Scores!$E$2:$E$263,Scores!$A$2:$A$263,$A10,Scores!$B$2:$B$263,B$1,Scores!$D$2:$D$263,"doctrine"),"") | C10: =IFERROR(AVERAGEIFS(Scores!$E$2:$E$263,Scores!$A$2:$A$263,$A10,Scores!$B$2:$B$263,C$1,Scores!$D$2:$D$263,"doctrine"),"") | D10: =IFERROR(AVERAGEIFS(Scores!$E$2:$E$263,Scores!$A$2:$A$263,$A10,Scores!$B$2:$B$263,D$1,Scores!$D$2:$D$263,"doctrine"),"") | E10: =IFERROR(AVERAGEIFS(Scores!$E$2:$E$263,Scores!$A$2:$A$263,$A10,Scores!$B$2:$B$263,E$1,Scores!$D$2:$D$263,"doctrine"),"") | F10: =IFERROR(AVERAGEIFS(Scores!$E$2:$E$263,Scores!$A$2:$A$263,$A10,Scores!$B$2:$B$263,F$1,Scores!$D$2:$D$263,"doctrine"),"") | G10: =IFERROR(AVERAGEIFS(Scores!$E$2:$E$263,Scores!$A$2:$A$263,$A10,Scores!$B$2:$B$263,G$1,Scores!$D$2:$D$263,"doctrine"),"") | H10: =IFERROR(AVERAGEIFS(Scores!$E$2:$E$263,Scores!$A$2:$A$263,$A10,Scores!$B$2:$B$263,H$1,Scores!$D$2:$D$263,"doctrine"),"") | I10: =COUNT(B10:H10) -> 0
A11: neoreaction | B11: =IFERROR(AVERAGEIFS(Scores!$E$2:$E$263,Scores!$A$2:$A$263,$A11,Scores!$B$2:$B$263,B$1,Scores!$D$2:$D$263,"doctrine"),"") | C11: =IFERROR(AVERAGEIFS(Scores!$E$2:$E$263,Scores!$A$2:$A$263,$A11,Scores!$B$2:$B$263,C$1,Scores!$D$2:$D$263,"doctrine"),"") | D11: =IFERROR(AVERAGEIFS(Scores!$E$2:$E$263,Scores!$A$2:$A$263,$A11,Scores!$B$2:$B$263,D$1,Scores!$D$2:$D$263,"doctrine"),"") | E11: =IFERROR(AVERAGEIFS(Scores!$E$2:$E$263,Scores!$A$2:$A$263,$A11,Scores!$B$2:$B$263,E$1,Scores!$D$2:$D$263,"doctrine"),"") | F11: =IFERROR(AVERAGEIFS(Scores!$E$2:$E$263,Scores!$A$2:$A$263,$A11,Scores!$B$2:$B$263,F$1,Scores!$D$2:$D$263,"doctrine"),"") | G11: =IFERROR(AVERAGEIFS(Scores!$E$2:$E$263,Scores!$A$2:$A$263,$A11,Scores!$B$2:$B$263,G$1,Scores!$D$2:$D$263,"doctrine"),"") | H11: =IFERROR(AVERAGEIFS(Scores!$E$2:$E$263,Scores!$A$2:$A$263,$A11,Scores!$B$2:$B$263,H$1,Scores!$D$2:$D$263,"doctrine"),"") | I11: =COUNT(B11:H11) -> 0
A12: absolutisme | B12: =IFERROR(AVERAGEIFS(Scores!$E$2:$E$263,Scores!$A$2:$A$263,$A12,Scores!$B$2:$B$263,B$1,Scores!$D$2:$D$263,"doctrine"),"") | C12: =IFERROR(AVERAGEIFS(Scores!$E$2:$E$263,Scores!$A$2:$A$263,$A12,Scores!$B$2:$B$263,C$1,Scores!$D$2:$D$263,"doctrine"),"") | D12: =IFERROR(AVERAGEIFS(Scores!$E$2:$E$263,Scores!$A$2:$A$263,$A12,Scores!$B$2:$B$263,D$1,Scores!$D$2:$D$263,"doctrine"),"") | E12: =IFERROR(AVERAGEIFS(Scores!$E$2:$E$263,Scores!$A$2:$A$263,$A12,Scores!$B$2:$B$263,E$1,Scores!$D$2:$D$263,"doctrine"),"") | F12: =IFERROR(AVERAGEIFS(Scores!$E$2:$E$263,Scores!$A$2:$A$263,$A12,Scores!$B$2:$B$263,F$1,Scores!$D$2:$D$263,"doctrine"),"") | G12: =IFERROR(AVERAGEIFS(Scores!$E$2:$E$263,Scores!$A$2:$A$263,$A12,Scores!$B$2:$B$263,G$1,Scores!$D$2:$D$263,"doctrine"),"") | H12: =IFERROR(AVERAGEIFS(Scores!$E$2:$E$263,Scores!$A$2:$A$263,$A12,Scores!$B$2:$B$263,H$1,Scores!$D$2:$D$263,"doctrine"),"") | I12: =COUNT(B12:H12) -> 0
A13: ecosocialisme | B13: =IFERROR(AVERAGEIFS(Scores!$E$2:$E$263,Scores!$A$2:$A$263,$A13,Scores!$B$2:$B$263,B$1,Scores!$D$2:$D$263,"doctrine"),"") | C13: =IFERROR(AVERAGEIFS(Scores!$E$2:$E$263,Scores!$A$2:$A$263,$A13,Scores!$B$2:$B$263,C$1,Scores!$D$2:$D$263,"doctrine"),"") | D13: =IFERROR(AVERAGEIFS(Scores!$E$2:$E$263,Scores!$A$2:$A$263,$A13,Scores!$B$2:$B$263,D$1,Scores!$D$2:$D$263,"doctrine"),"") | E13: =IFERROR(AVERAGEIFS(Scores!$E$2:$E$263,Scores!$A$2:$A$263,$A13,Scores!$B$2:$B$263,E$1,Scores!$D$2:$D$263,"doctrine"),"") | F13: =IFERROR(AVERAGEIFS(Scores!$E$2:$E$263,Scores!$A$2:$A$263,$A13,Scores!$B$2:$B$263,F$1,Scores!$D$2:$D$263,"doctrine"),"") | G13: =IFERROR(AVERAGEIFS(Scores!$E$2:$E$263,Scores!$A$2:$A$263,$A13,Scores!$B$2:$B$263,G$1,Scores!$D$2:$D$263,"doctrine"),"") | H13: =IFERROR(AVERAGEIFS(Scores!$E$2:$E$263,Scores!$A$2:$A$263,$A13,Scores!$B$2:$B$263,H$1,Scores!$D$2:$D$263,"doctrine"),"") | I13: =COUNT(B13:H13) -> 0
... A17: neocameralisme | B17: =IFERROR(AVERAGEIFS(Scores!$E$2:$E$263,Scores!$A$2:$A$263,$A17,Scores!$B$2:$B$263,B$1,Scores!$D$2:$D$263,"doctrine"),"") | C17: =IFERROR(AVERAGEIFS(Scores!$E$2:$E$263,Scores!$A$2:$A$263,$A17,Scores!$B$2:$B$263,C$1,Scores!$D$2:$D$263,"doctrine"),"") | D17: =IFERROR(AVERAGEIFS(Scores!$E$2:$E$263,Scores!$A$2:$A$263,$A17,Scores!$B$2:$B$263,D$1,Scores!$D$2:$D$263,"doctrine"),"") | E17: =IFERROR(AVERAGEIFS(Scores!$E$2:$E$263,Scores!$A$2:$A$263,$A17,Scores!$B$2:$B$263,E$1,Scores!$D$2:$D$263,"doctrine"),"") | F17: =IFERROR(AVERAGEIFS(Scores!$E$2:$E$263,Scores!$A$2:$A$263,$A17,Scores!$B$2:$B$263,F$1,Scores!$D$2:$D$263,"doctrine"),"") | G17: =IFERROR(AVERAGEIFS(Scores!$E$2:$E$263,Scores!$A$2:$A$263,$A17,Scores!$B$2:$B$263,G$1,Scores!$D$2:$D$263,"doctrine"),"") | H17: =IFERROR(AVERAGEIFS(Scores!$E$2:$E$263,Scores!$A$2:$A$263,$A17,Scores!$B$2:$B$263,H$1,Scores!$D$2:$D$263,"doctrine"),"") | I17: =COUNT(B17:H17) -> 0
A19: Lecture : 0 = pôle planifié (rouge), 10 = pôle marchand (ocre). Vue en lecture seule, alimentée par l'onglet Scores.

Sheet Listes
A1: familles | B1: nom famille | C1: modules | D1: verdicts | E1: types_relation | F1: couches | G1: statuts | H1: oui_non
A2: liberalismes | B2: Libéralismes | C2: nationalisme | D2: vrai | E2: derive | F2: doctrine | G2: a_rediger | H2: oui
A3: republicanismes | B3: Républicanismes | C3: populisme | D3: faux | E3: synthese | F3: historique | G3: brouillon | H3: non
A4: socialismes | B4: Socialismes | C4: religiosite | D4: nuance | E4: rupture | G4: relu
A5: marxismes | B5: Marxismes | C5: technophilie | D5: depend | E5: opposition | G5: publie
A6: anarchismes | B6: Anarchismes | C6: souverainisme
A7: conservatismes | B7: Conservatismes
A8: traditionalismes | B8: Traditionalismes et réaction
A9: fascismes | B9: Fascismes
A10: autoritarismes | B10: Autoritarismes non fascistes
A11: ecologismes | B11: Écologismes
A12: emancipations | B12: Émancipations
A13: anticolonialismes | B13: Anticolonialismes et tiers-mondismes
A14: religieux | B14: Politiques religieuses
A15: technopolitiques | B15: Technopolitiques
